Workbook

Sheet All_Weather
B1: DBC | C1: COMT | D1: GLD | E1: IEF | F1: TLT | G1: VTI | H1: SPMO | I1: SHY | J1: TIP | K1: Cash GBP/CHF | L1: DBC | M1: COMT | N1: GLD | O1: IEF | P1: TLT | Q1: VTI | R1: SPMO | S1: SHY | T1: TIP | U1: GBP_USD | V1: CHF_USD | W1: Total Stock | X1: Tot Cash $ | Y1: Rem. Cash
A2: 43802 | B2: 20 | D2: 2 | E2: 5 | F2: 8 | G2: 10 | K2: 4000 | L2: 15.28 | N2: 139.3 | O2: 112.09 | P2: 141.5 | Q2: 159 | U2: 1.30038 | W2: =SUMPRODUCT(B2:G2,L2:Q2) -> 3866.65 | X2: =K2*U2 -> 5201.52 | Y2: =X2-W2 -> 1334.87
A3: 43471 | B3: 18 | D3: 2 | E3: 6 | F3: 9 | G3: 10 | K3: 2200 | L3: 16.245 | N3: 147.365 | O3: 111.415 | P3: 138.748 | Q3: 164.2 | U3: 1.31572 | W3: =SUMPRODUCT(B3:G3,L3:Q3) -> 4146.362 | X3: =K3*U3+Y2 -> 4229.454 | Y3: =X3-W3 -> 83.092
A4: 43865 | B4: 0 | D4: 2 | E4: 6 | F4: 9 | G4: 11 | K4: 4000 | N4: 146.115 | O4: 113.055 | P4: 143.325 | Q4: 167.6 | U4: 1.3012 | W4: =SUMPRODUCT(B4:G4,L4:Q4) -> 4104.085 | X4: =K4*U4+Y3 -> 5287.892 | Y4: =X4-W4 -> 1183.807
A5: 43895 | B5: 0 | D5: 2 | E5: 6 | F5: 9 | G5: 11 | K5: 4000 | N5: 157.165 | O5: 119.17 | P5: 157.675 | Q5: 152.97 | U5: 1.2945 | W5: =SUMPRODUCT(B5:G5,L5:Q5) -> 4131.095 | X5: =K5*U5+Y4 -> 6361.807 | Y5: =X5-W5 -> 2230.712
A6: 43920 | B6: =26*3 -> 78 | D6: 2 | E6: 5 | F6: 7 | G6: 12 | K6: 6000 | L6: =(11.325*73+11.335*5)/78 -> 11.325641 | N6: 151.865 | O6: 121.255 | P6: 166.31 | Q6: 130.67 | U6: 1.24027 | W6: =SUMPRODUCT(B6:G6,L6:Q6) -> 4525.615 | X6: =K6*U6+Y5 -> 9672.332 | Y6: =X6-W6 -> 5146.717
A7: 43920 | G7: 30 | Q7: 130.67 | U7: 1.24027 | W7: =SUMPRODUCT(B7:G7,L7:Q7) -> 3920.1 | X7: =K7*U7+Y6 -> 5146.717 | Y7: =X7-W7 -> 1226.617
A8: 43952 | B8: 28 | D8: 2 | E8: 5 | F8: 7 | G8: 11 | K8: 4000 | L8: 10.765 | N8: 159.63 | O8: 121.755 | P8: 167.44 | Q8: 142.35318 | U8: 1.25275 | W8: =SUMPRODUCT(B8:G8,L8:Q8) -> 3967.42 | X8: =K8*U8+Y7 -> 6237.617 | Y8: =X8-W8 -> 2270.197
A9: 43983 | B9: 25 | D9: 2 | E9: 5 | F9: 7 | G9: 10 | K9: 4000 | L9: 11.725 | N9: 162.96 | O9: 121.615 | P9: 162.095 | Q9: 153.575 | U9: 1.2394 | W9: =SUMPRODUCT(B9:G9,L9:Q9) -> 3897.535 | X9: =K9*U9+Y8 -> 7227.797 | Y9: =X9-W9 -> 3330.262
A10: 44014 | B10: 50 | D10: 3 | E10: 8 | F10: 12 | G10: 0 | K10: 1000 | L10: 12.485 | N10: 167.035 | O10: 121.685 | P10: 163.42 | Q10: 159.5 | U10: 1.24615 | W10: =SUMPRODUCT(B10:G10,L10:Q10) -> 4059.875 | X10: =K10*U10+Y9 -> 4576.412 | Y10: =X10-W10 -> 516.537
A11: 44074 | B11: 45 | D11: 2 | E11: 9 | F11: 11 | G11: 1 | K11: 2800 | L11: 12.89 | N11: 185.16 | O11: 122.75 | P11: 170.6 | Q11: 164.02 | U11: 1.31225 | W11: =SUMPRODUCT(B11:G11,L11:Q11) -> 4095.74 | X11: =K11*U11+Y10 -> 4190.837 | Y11: =X11-W11 -> 95.097
A12: 44081 | B12: 16 | D12: 2 | E12: 6 | F12: 9 | G12: 8 | K12: 4000 | L12: 12.785 | N12: 179.47 | O12: 121.755 | P12: =(1315.16+164.39)/9 -> 164.39444 | Q12: 170 | U12: 1.3167 | W12: =SUMPRODUCT(B12:G12,L12:Q12) -> 4133.58 | X12: =K12*U12+Y11 -> 5361.897 | Y12: =X12-W12 -> 1228.317
A13: 44110 | B13: 18 | D13: 1 | E13: 4 | F13: 11 | G13: 6 | K13: 3000 | L13: 13.145 | N13: 177.78 | O13: 121.265 | P13: 160.83 | Q13: =(171.8*5+171.83*1)/6 -> 171.805 | U13: 1.29065 | W13: =SUMPRODUCT(B13:G13,L13:Q13) -> 3699.41 | X13: =K13*U13+Y12 -> 5100.267 | Y13: =X13-W13 -> 1400.857
A14: 44141 | B14: 29 | D14: 2 | E14: 6 | F14: 8 | G14: 8 | K14: 3000 | L14: 13.105 | N14: 183.345 | O14: 120.535 | P14: 159.68 | Q14: =(179.355+179.43)/2 -> 179.3925 | U14: 1.3157 | W14: =SUMPRODUCT(B14:G14,L14:Q14) -> 4182.525 | X14: =K14*U14+Y13 -> 5347.957 | Y14: =X14-W14 -> 1165.432
A15: 44169 | B15: 6 | D15: 3 | E15: 7 | F15: 14 | G15: 3 | K15: 3000 | L15: 14.09 | N15: 172.26 | O15: 119.34 | P15: 155.34 | Q15: 190.97 | U15: 1.3489 | W15: =SUMPRODUCT(B15:G15,L15:Q15) -> 4184.37 | X15: =K15*U15+Y14 -> 5212.132 | Y15: =X15-W15 -> 1027.762
A16: 44200 | B16: 10 | D16: 1 | E16: 6 | F16: 7 | G16: 10 | K16: 4000 | L16: 14.685 | N16: 182.14 | O16: 120.02 | P16: 157.835 | Q16: 191.47 | U16: 1.35515 | W16: =SUMPRODUCT(B16:G16,L16:Q16) -> 4068.655 | X16: =K16*U16+Y15 -> 6448.362 | Y16: =X16-W16 -> 2379.707
A17: 44228 | D17: 4 | F17: 18 | K17: 10000 | L17: 16.77 | N17: =(160.72+160.775*3)/4 -> 160.76125 | O17: 115.17 | P17: 139.925 | Q17: 201.41 | U17: 1.39622 | W17: =SUMPRODUCT(B17:G17,L17:Q17) -> 3161.695 | X17: =K17*U17+Y16 -> 16341.907 | Y17: =X17-W17 -> 13180.212
A18: 44348 | B18: -54 | G18: -8 | L18: 18.905 | N18: 178.16 | O18: 114.29 | P18: 138.15 | Q18: 218.44 | W18: =SUMPRODUCT(B18:G18,L18:Q18) -> -2768.39 | X18: =K18*U18+Y17 -> 13180.212 | Y18: =X18-W18 -> 15948.602
A19: 44378 | E19: 11 | F19: 12 | O19: 114.285 | P19: 138.095 | W19: =SUMPRODUCT(B19:G19,L19:Q19) -> 2914.275 | Y19: =X19-W19 -> -2914.275
A20: 44397 | K20: 1000 | U20: 1.35915 | Y20: =X20-W20 -> 0
A21: 44432 | B21: 14 | D21: 2 | L21: 18.925 | N21: 169.015 | O21: 117.29 | P21: 149.56 | Q21: 231.03 | W21: =SUMPRODUCT(B21:G21,L21:Q21) -> 602.98 | Y21: =X21-W21 -> -602.98
A22: 44439 | K22: 3000 | U22: 1.3751 | X22: =K22*U22+Y21+K22*V22 -> 3522.32 | Y22: =X22-W22 -> 3522.32
A23: 44447 | K23: 3000 | U23: 1.3754 | X23: =K23*U23+Y22+K23*V23 -> 7648.52 | Y23: =X23-W23 -> 7648.52
A24: 44459 | K24: 2000 | U24: 1.3662 | X24: =K24*U24+Y23+K24*V24 -> 10380.92 | Y24: =X24-W24 -> 10380.92
A25: 44474 | B25: 0 | D25: 2 | E25: 8 | F25: 6 | G25: 9 | K25: 2000 | L25: 21.01 | N25: 163.76 | O25: 115.025 | P25: 143.655 | Q25: 224.62 | U25: 1.36275 | W25: =SUMPRODUCT(B25:G25,L25:Q25) -> 4131.23 | X25: =K25*U25+Y24+K25*V25 -> 13106.42 | Y25: =X25-W25 -> 8975.19
A26: 44474 | K26: 8900 | V26: 1.07695 | X26: =K26*U26+Y25+K26*V26 -> 18560.045 | Y26: =X26-W26 -> 18560.045
A27: 44491 | K27: 10000 | U27: 1.3782 | X27: =K27*U27+Y26+K27*V27 -> 32342.045 | Y27: =X27-W27 -> 32342.045
A28: 44491 | K28: 1100 | V28: 1.09235 | X28: =K28*U28+Y27+K28*V28 -> 33543.63 | Y28: =X28-W28 -> 33543.63
A29: 44498 | K29: 10000 | V29: 1.0961 | X29: =K29*U29+Y28+K29*V29 -> 44504.63 | Y29: =X29-W29 -> 44504.63
A30: 44503 | K30: 20000 | V30: =(1.09585+1.09485)/2 -> 1.09535 | X30: =K30*U30+Y29+K30*V30 -> 66411.63 | Y30: =X30-W30 -> 66411.63
A31: 44512 | D31: 1 | E31: 9 | F31: 11 | L31: 21.35 | N31: 174.185 | O31: 114.615 | P31: 147.335 | Q31: 241.4 | W31: =SUMPRODUCT(B31:G31,L31:Q31) -> 2826.405 | Y31: =X31-W31 -> -2826.405
A32: 44524 | K32: 3000 | V32: 1.0704 | X32: =K32*U32+Y31+K32*V32 -> 384.795 | Y32: =X32-W32 -> 384.795
A33: 44533 | E33: -3 | F33: -10 | O33: 116.34 | P33: 153.925 | W33: =SUMPRODUCT(B33:G33,L33:Q33) -> -1888.27 | X33: =K33*U33+Y32+K33*V33 -> 384.795 | Y33: =X33-W33 -> 2273.065
A34: 44533 | B34: 22 | D34: 1 | G34: 5 | L34: 19.54 | N34: 166.34 | Q34: 231.05 | W34: =SUMPRODUCT(B34:G34,L34:Q34) -> 1751.47 | Y34: =X34-W34 -> -1751.47
A35: 44594 | K35: 7000 | V35: 1.08855 | X35: =K35*U35+Y34+K35*V35-1.89 -> 5866.49 | Y35: =X35-W35 -> 5866.49
A36: 44615 | K36: 10000 | V36: 1.08925 | X36: =K36*U36+Y35+K36*V36-1.89 -> 16757.1 | Y36: =X36-W36 -> 16757.1
A37: 44690 | B37: -5 | L37: 26.99 | W37: =SUMPRODUCT(B37:G37,L37:Q37) -> -134.95 | Y37: =X37-W37 -> 134.95
A38: 44868 | V38: 0.987 | X38: =K38*U38+Y37+K38*V38-1.89 -> 133.06 | Y38: =X38-W38 -> 133.06
A39: 44911 | B39: -320 | L39: 24.26 | W39: =SUMPRODUCT(B39:G39,L39:Q39) -> -7763.2 | Y39: =X39-W39 -> 7763.2
A40: 44978 | C40: 197 | F40: 23 | M40: 27.47 | P40: 100.545 | W40: =SUMPRODUCT(B40:G40,L40:Q40) -> 7724.125 | Y40: =X40-W40 -> -7724.125
...

Sheet Dividend portfolio
B1: Qty | O1: Price
A2: Date | B2: RIO | C2: CTO | D2: OBDC | E2: EPD | F2: HTGC | G2: ABR | H2: ARCC | I2: PDX | J2: IBM | K2: CVS | L2: VZ | M2: ABBV | N2: IIPR | O2: RIO | P2: CTO | Q2: OBDC | R2: EPD | S2: HTGC | T2: ABR | U2: ARCC | V2: PDX | W2: IBM | X2: CVS | Y2: VZ | Z2: ABBV | AA2: IIPR | AC2: Total
A3: 44491 | B3: 17 | C3: 63 | E3: 46 | F3: 64 | G3: 56 | I3: 85 | J3: 9 | L3: 21 | M3: 10 | O3: 66.145 | P3: 17.86 | R3: 24.275 | S3: 17.385 | T3: 19.775 | V3: 13.12 | W3: 129.7 | Y3: 53.185 | Z3: 108.76 | AC3: =SUMPRODUCT(O3:AA3,B3:N3) -> 10073.32
A4: 44498 | B4: 18 | C4: 60 | E4: 47 | F4: 63 | G4: 55 | I4: 85 | J4: 9 | L4: 21 | M4: 10 | O4: 63.4 | P4: 18.11 | R4: 22.945 | S4: 17.655 | T4: 20.195 | V4: 13.105 | W4: 125.72 | Y4: 52.845 | Z4: 114.37 | AC4: =SUMPRODUCT(O4:AA4,B4:N4) -> 10028.055
A5: 44503 | B5: 17 | C5: 60 | E5: 51 | F5: 62 | G5: 54 | I5: 83 | J5: 8 | L5: 21 | M5: 9 | O5: 61.68 | P5: 18.09 | R5: 22.195 | S5: 17.825 | T5: =(19.575*21+33*19.575)/54 -> 19.575 | V5: 13.285 | W5: 126.615 | Y5: 52.855 | Z5: 117.085 | AC5: =SUMPRODUCT(O5:AA5,B5:N5) -> 9707.4
A6: 44512 | B6: 7 | C6: 15 | E6: 16 | F6: 25 | G6: 26 | I6: 9 | J6: 5 | L6: 8 | M6: 3 | O6: 62.495 | P6: 18.61 | R6: 23.125 | S6: 17.185 | T6: 19.315 | V6: 14.145 | W6: 119.14 | Y6: 52.42 | Z6: 116.825 | AC6: =SUMPRODUCT(O6:AA6,B6:N6) -> 3511.27
A7: 44868 | N7: 46 | AA7: 114.7487 | AC7: =SUMPRODUCT(O7:AA7,B7:N7) -> 5278.4402
A8: 44869 | B8: 26 | C8: 55 | E8: 50 | F8: 120 | G8: 195 | I8: 65 | J8: 8 | L8: 70 | M8: 4 | N8: 1 | O8: 57.79154 | P8: 20.4 | R8: 24.85 | S8: 14.765 | T8: 14.405 | V8: 15.645 | W8: 136.385 | Y8: 36.985 | Z8: 143.93 | AA8: 111.075 | AC8: =SUMPRODUCT(O8:AA8,B8:N8) -> 13831.605
A9: 44911 | E9: -214 | R9: 23.552336 | AC9: =SUMPRODUCT(O9:AA9,B9:N9) -> -5040.2
A10: 44978 | C10: 57 | F10: 21 | I10: 55 | J10: 6 | L10: 9 | M10: 3 | N10: 25 | P10: 18.66 | S10: 15.635 | V10: 15.035 | W10: 131.91 | Y10: 39.22 | Z10: 151.86 | AA10: 83.61 | AC10: =SUMPRODUCT(O10:AA10,B10:N10) -> 5909.15
A11: 44929 | C11: 24 | F11: 9 | J11: 2 | L11: 5 | P11: 17.28 | S11: 15.265 | W11: 128 | Y11: 38.275 | AC11: =SUMPRODUCT(O11:AA11,B11:N11) -> 999.48
A12: 45009 | G12: 45 | T12: 11.135 | AC12: =SUMPRODUCT(O12:AA12,B12:N12) -> 501.075
A13: 45320 | B13: 6 | C13: 60 | G13: 12 | I13: -45 | J13: -8 | L13: 10 | M13: 5 | O13: 70.825 | P13: 16.88 | S13: 17.61 | T13: 14.265 | V13: 19.65 | W13: 186.32 | Y13: 41.86 | Z13: 164.59 | AA13: 96.16 | AC13: =SUMPRODUCT(O13:AA13,B13:N13) -> 475.67
A14: 45371 | B14: 14 | C14: 7 | F14: -39 | I14: -17 | J14: -1 | L14: 8 | M14: -3 | O14: 63.31 | P14: 16.69 | S14: 18.215 | V14: 20.765 | W14: 192.495 | Y14: 39.865 | Z14: 176.58 | AC14: =SUMPRODUCT(O14:AA14,B14:N14) -> -463.535
A15: 45712 | F15: -37 | I15: -374 | J15: -7 | M15: -1 | S15: 21.44 | V15: 25.3 | W15: 262.5 | Z15: 203.94 | AC15: =SUMPRODUCT(O15:AA15,B15:N15) -> -12296.92
A16: 45884 | G16: -600 | T16: 11 | AC16: =SUMPRODUCT(O16:AA16,B16:N16) -> -6600
A17: 45887 | H17: 300 | U17: 22.365 | AC17: =SUMPRODUCT(O17:AA17,B17:N17) -> 6709.5
A18: 45888 | C18: -484 | D18: 564 | G18: -52 | P18: 16.56863 | Q18: 14.165 | T18: 11.43 | AC18: =SUMPRODUCT(O18:AA18,B18:N18) -> -624.51692
A19: 45894 | J19: -32.4964 | K19: 100 | W19: 240.54753 | X19: 71.04 | AC19: =SUMPRODUCT(O19:AA19,B19:N19) -> -712.92875
A21: Dividends | B21: =17+5 -> 22 | C21: =66+8+9 -> 83 | E21: 4 | F21: =103+17 -> 120 | G21: =173+19+17 -> 209 | I21: 54 | J21: 1.4964 | L21: =20+3+3 -> 26 | M21: 1 | N21: =9+2+3 -> 14
A26: Qty | B26: =sum(B3:B25) -> 127 | C26: =sum(C3:C25) -> 0 | D26: =sum(D3:D25) -> 564 | E26: =sum(E3:E25) -> 0 | F26: =sum(F3:F25) -> 408 | G26: =sum(G3:G25) -> 0 | H26: =sum(H3:H25) -> 300 | I26: =sum(I3:I25) -> 0 | ... N26: =sum(N3:N25) -> 86 | P26: Invested | R26: Current value | S26: Gain | T26: IRR
B27: =IFERROR(__xludf.DUMMYFUNCTION("B26*GOOGLEFINANCE(B2, ""price"")"),9137.65) -> 9137.65 | C27: =IFERROR(__xludf.DUMMYFUNCTION("C26*GOOGLEFINANCE(C2, ""price"")"),0.0) -> 0 | D27: =IFERROR(__xludf.DUMMYFUNCTION("D26*GOOGLEFINANCE(D2, ""price"")"),7427.88) -> 7427.88 | E27: =IFERROR(__xludf.DUMMYFUNCTION("E26*GOOGLEFINANCE(E2, ""price"")"),0.0) -> 0 | F27: =IFERROR(__xludf.DUMMYFUNCTION("F26*GOOGLEFINANCE(F2, ""price"")"),7344.0) -> 7344 | G27: =IFERROR(__xludf.DUMMYFUNCTION("G26*GOOGLEFINANCE(G2, ""price"")"),0.0) -> 0 | H27: =IFERROR(__xludf.DUMMYFUNCTION("H26*GOOGLEFINANCE(H2, ""price"")"),6186.0) -> 6186 | I27: =IFERROR(__xludf.DUMMYFUNCTION("I26*GOOGLEFINANCE(I2, ""price"")"),0.0) -> 0 | J27: =IFERROR(__xludf.DUMMYFUNCTION("J26*GOOGLEFINANCE(J2, ""price"")"),-4.1111114512659697E-13) -> 0 | K27: =IFERROR(__xludf.DUMMYFUNCTION("K26*GOOGLEFINANCE(K2, ""price"")"),8036.0) -> 8036 | L27: =IFERROR(__xludf.DUMMYFUNCTION("L26*GOOGLEFINANCE(L2, ""price"")"),8180.89) -> 8180.89 | M27: =IFERROR(__xludf.DUMMYFUNCTION("M26*GOOGLEFINANCE(M2, ""price"")"),9335.699999999999) -> 9335.7 | N27: =IFERROR(__xludf.DUMMYFUNCTION("N26*GOOGLEFINANCE(N2, ""price"")"),4252.7) -> 4252.7 | P27: =sum(AC3:AC25)+722 -> 42008.865 | R27: =SUM(B27:N27) -> 59900.82 | S27: =R27-P27 -> 17891.955 | T27: =((R27/P27)^(1/YEARFRAC(A3, today()))) - 1 -> 0.090266115
A28: Current | B28: =B27/$R$27 -> 0.15254633 | C28: =C27/$R$27 -> 0 | D28: =D27/$R$27 -> 0.12400298 | E28: =E27/$R$27 -> 0 | F28: =F27/$R$27 -> 0.12260266 | G28: =G27/$R$27 -> 0 | H28: =H27/$R$27 -> 0.10327071 | I28: =I27/$R$27 -> 0 | ... N28: =N27/$R$27 -> 0.070995689
A29: Target | B29: =100%/(count(B26:N26)-1) -> 0.083333333 | C29: =B29 -> 0.083333333 | D29: =C29 -> 0.083333333 | E29: =C29 -> 0.083333333 | F29: =E29 -> 0.083333333 | G29: 0 | H29: 0.1 | I29: 0 | J29: 0.1 | K29: 0.1 | L29: =J29 -> 0.1 | M29: =L29 -> 0.1 | N29: =M29 -> 0.1
B31: =$O$31*B29 -> 4490.8333 | C31: =$O$31*C29 -> 4490.8333 | D31: =$O$31*D29 -> 4490.8333 | E31: =$O$31*E29 -> 4490.8333 | F31: =$O$31*F29 -> 4490.8333 | G31: =$O$31*G29 -> 0 | H31: =$O$31*H29 -> 5389 | I31: =$O$31*I29 -> 0 | J31: =$O$31*J29 -> 5389 | L31: =$O$31*L29 -> 5389 | M31: =$O$31*M29 -> 5389 | N31: =$O$31*N29 -> 5389 | O31: 53890
B32: =B31-B27 -> -4646.8167 | C32: =C31-C27 -> 4490.8333 | D32: =D31-D27 -> -2937.0467 | E32: =E31-E27 -> 4490.8333 | F32: =F31-F27 -> -2853.1667 | G32: =G31-G27 -> 0 | H32: =H31-H27 -> -797 | I32: =I31-I27 -> 0 | J32: =J31-J27 -> 5389 | L32: =L31-L27 -> -2791.89 | M32: =M31-M27 -> -3946.7 | N32: =N31-N27 -> 1136.3

Sheet Long Term
A1: GOOGL | B1: Qty | C1: Price | D1: Amount | E1: Comment | G1: Options P&L
A2: 44804 | B2: 22 | C2: 109.37 | D2: =B2*C2*-1 -> -2406.14 | H2: ASAN | I2: CROX | J2: GOOGL | K2: AAPL | L2: WING | M2: RCAT | N2: NVDA | O2: LHDX | P2: All others
A3: 44806 | B3: 100 | C3: 108 | D3: =B3*C3*-1 -> -10800 | G3: 2022 | H3: 3528 | I3: 228 | J3: 943 | O3: 667 | P3: -282 | Q3: =SUM(H3:P3) -> 5084
A4: 45341 | B4: -100 | C4: 140 | D4: =B4*C4*-1 -> 14000 | G4: 2023 | H4: 3805 | I4: 4275 | J4: 1019 | K4: 2040 | P4: -3940 | Q4: =SUM(H4:P4) -> 7199 | R4: =Q4/Q3-1 -> 0.41601101
A5: 45492 | B5: 100 | C5: 180 | D5: =B5*C5*-1 -> -18000 | E5: Put assigned | G5: 2024 | H5: =sumif('Options 2024'!B3:B108,"ASAN",'Options 2024'!Q3:Q108) -> 2591.2 | I5: =sumif('Options 2024'!B3:B108,"CROX",'Options 2024'!Q3:Q108) -> 3802.79 | J5: =sumif('Options 2024'!B3:B108,"GOOGL",'Options 2024'!Q3:Q108) -> 2617.79 | K5: =sumif('Options 2024'!B3:B108,"AAPL",'Options 2024'!Q3:Q108) -> 2708.72 | P5: =sum('Options 2024'!Q3:Q120)-sum(H5:K5) -> 228.19 | Q5: =SUM(H5:P5) -> 11948.69 | R5: =Q5/Q4-1 -> 0.6597708
A6: 45646 | B6: -100 | C6: 187.5 | D6: =B6*C6*-1 -> 18750 | G6: 2025 | H6: =sumif('Options 2025'!B3:B169,H2,'Options 2025'!Q3:Q168) -> 1088.45 | I6: =sumif('Options 2025'!B3:B169,I2,'Options 2025'!Q3:Q168) -> 2257.24 | J6: =sumif('Options 2025'!B3:B169,J2,'Options 2025'!Q3:Q168) -> 1150.44 | K6: =sumif('Options 2025'!B3:B169,K2,'Options 2025'!Q3:Q168) -> 1049.6 | L6: =sumif('Options 2025'!B3:B169,L2,'Options 2025'!Q3:Q168) -> 3300.7 | M6: =sumif('Options 2025'!$B3:$B169,M2,'Options 2025'!$Q3:$Q168) -> 2062.78 | N6: =sumif('Options 2025'!B3:B169,N2,'Options 2025'!Q3:Q168) -> 2006.85 | P6: =sum('Options 2025'!Q3:Q181)-sum(H6:N6) -> 11039.07 | Q6: =SUM(H6:P6) -> 23955.13 | R6: =Q6/Q5-1 -> 1.0048332
A7: 45678 | B7: 100 | C7: 180 | D7: =B7*C7*-1 -> -18000 | E7: Put assigned | G7: Total | H7: =SUM(H3:H6) -> 11012.65 | I7: =SUM(I3:I6) -> 10563.03 | J7: =SUM(J3:J6) -> 5730.23 | K7: =SUM(K3:K6) -> 5798.32 | L7: =SUM(L3:L6) -> 3300.7 | M7: =SUM(M3:M6) -> 2062.78 | N7: =SUM(N3:N6) -> 2006.85 | O7: =SUM(O3:O6) -> 667 | ... Q7: =SUM(Q3:Q6) -> 48186.82
B8: =SUM(B2:B7) -> 122 | D8: =SUM(D2:D7) -> -16456.14
G9: Stock P&L | H9: =IFERROR(__xludf.DUMMYFUNCTION("D30+B30*GOOGLEFINANCE(H2, ""price"")"),-11158.0) -> -11158 | I9: =IFERROR(__xludf.DUMMYFUNCTION("D63+GOOGLEFINANCE(I2, ""price"")*B63"),-3070.290000000001) -> -3070.29 | J9: =IFERROR(__xludf.DUMMYFUNCTION("D8+GOOGLEFINANCE(J2, ""price"")*B8"),22605.82) -> 22605.82 | K9: =IFERROR(__xludf.DUMMYFUNCTION("D121+GOOGLEFINANCE(K2,""Price"")*B121"),7385.000000000004) -> 7385 | L9: =IFERROR(__xludf.DUMMYFUNCTION("D66+GOOGLEFINANCE(L2,""Price"")*B66"),4473.0) -> 4473 | M9: =IFERROR(__xludf.DUMMYFUNCTION("D80+GOOGLEFINANCE(M2,""Price"")*B80"),-840.0) -> -840 | N9: =IFERROR(__xludf.DUMMYFUNCTION("D74+GOOGLEFINANCE(N2,""Price"")*B74"),5698.0) -> 5698 | O9: =D169 -> -10112.52 | Q9: =SUM(H9:P9) -> 14981.01
A10: ASAN | B10: Qty | C10: Price | D10: Amount | E10: Comment
A11: 44592 | B11: 45 | C11: 52.08 | D11: =B11*C11*-1 -> -2343.6 | E11: Put assignment | G11: Grand total | H11: =H7+H9 -> -145.35 | I11: =I7+I9 -> 7492.74 | J11: =J7+J9 -> 28336.05 | K11: =K7+K9 -> 13183.32 | L11: =L7+L9 -> 7773.7 | M11: =M7+M9 -> 1222.78 | N11: =N7+N9 -> 7704.85 | O11: =O7+O9 -> -9445.52 | P11: =P7+P9 -> 7045.26 | Q11: =sum(H11:P11) -> 63167.83
B12: 55 | C12: 48.48 | D12: =B12*C12*-1 -> -2666.4 | E12: Put assignment
A13: 44638 | B13: 100 | C13: 50 | D13: =B13*C13*-1 -> -5000 | E13: Put assignment
A14: 44665 | B14: 100 | C14: 35 | D14: =B14*C14*-1 -> -3500 | E14: Put assignment
A15: 44701 | B15: 100 | C15: 25 | D15: =B15*C15*-1 -> -2500 | E15: Call assigned to compensate above
A16: 44911 | B16: 1000 | C16: 15 | D16: =B16*C16*-1 -> -15000 | E16: Put assignment
A17: 44975 | B17: -400 | C17: 15 | D17: =B17*C17*-1 -> 6000 | E17: Call Assigned
A18: 45002 | B18: -600 | C18: 16 | D18: =B18*C18*-1 -> 9600 | E18: Call Assigned
A19: 45037 | B19: 300 | C19: 20 | D19: =B19*C19*-1 -> -6000 | E19: Put assigned
A20: 45094 | B20: -300 | C20: 20 | D20: =B20*C20*-1 -> 6000 | E20: Call assigned
A21: 45247 | B21: -400 | C21: 17.5 | D21: =B21*C21*-1 -> 7000 | E21: Put assigned
A22: 45366 | B22: 200 | C22: 17.5 | D22: =C22*B22*-1 -> -3500 | E22: Put assigned
A23: 45366 | B23: 200 | C23: 17 | D23: =C23*B23*-1 -> -3400 | E23: Put assigned
A24: 45401 | B24: 400 | C24: 15 | D24: =C24*B24*-1 -> -6000 | E24: Put assigned
A25: 45429 | B25: -400 | C25: 15.5 | D25: =C25*B25*-1 -> 6200 | E25: Call assigned
A26: 45521 | B26: 400 | C26: 14 | D26: =C26*B26*-1 -> -5600 | E26: Put assigned
A27: 45611 | B27: -400 | C27: 12.5 | D27: =C27*B27*-1 -> 5000 | E27: Call assigned
A28: 45646 | B28: -400 | C28: 16 | D28: =C28*B28*-1 -> 6400 | E28: Call assigned
A29: 45729 | B29: 400 | C29: 17.5 | D29: =C29*B29*-1 -> -7000 | E29: Put assigned
B30: =SUM(B11:B29) -> 400 | D30: =SUM(D11:D29) -> -16310
A32: IBKR | B32: Qty | C32: Price | D32: Amount | E32: Comment
A33: 45982 | B33: 300 | C33: 62 | D33: =-B33*C33 -> -18600 | E33: Put assigned
A35: Total | B35: =sum(B33:B34) -> 300 | D35: =sum(D33:D34) -> -18600
A37: NLR | B37: Qty | C37: Price | D37: Amount | E37: Comment
A38: 45982 | B38: 100 | C38: 150 | D38: =-B38*C38 -> -15000 | E38: Put assigned
A40: Total | B40: =sum(B38:B39) -> 100 | D40: =sum(D38:D39) -> -15000
A42: GLW | B42: Qty | C42: Price | D42: Amount | E42: Comment
A43: 45982 | B43: 200 | C43: 80 | D43: =-B43*C43 -> -16000 | E43: Put assigned
A45: Total | B45: =sum(B43:B44) -> 200 | D45: =sum(D43:D44) -> -16000
A48: CROX | B48: Qty | C48: Price | D48: Amount | E48: Comment
...

Sheet Options 2022
A1: Trans date | B1: Tiker | C1: Type | D1: Action | E1: Expiration | F1: Strike | G1: Qty | H1: Amount | I1: Comission | J1: Total Profit | K1: Total loss | L1: Total P&L | M1: Comment | N1: IV | O1: Hist. volatility | P1: VIX | Q1: Max Win probab | R1: Max Lose probab | S1: Profit probability | T1: Max Loss | U1: Return / Risk | V1: Liquidity
A2: 44508 | B2: LHDX | C2: Call | D2: Sell | E2: Nov19'21 | F2: 7.5 | H2: 23 | I2: 0.17 | J2: =H2-I2 -> 22.83 | K2: 0 | L2: =sum(J2:K2) -> 22.83 | M2: expired OTM
A3: 44511 | B3: LHDX | C3: Call | D3: Sell | E3: Nov19'21 | F3: 7.5 | H3: 70 | I3: 1.02 | J3: =H3-I3 -> 68.98 | K3: 0 | L3: =sum(J3:K3) -> 68.98 | M3: expired OTM
A5: 44529 | B5: DBC | C5: Put | D5: Sell | E5: Dec17'21 | F5: 21 | H5: 105 | I5: 0.27 | J5: =H5-I5 -> 104.73 | K5: 0 | L5: =sum(J5:K5) -> 104.73 | M5: Assigned! But sold at 21. See next line
A6: 44517 | B6: LHDX | C6: Call | D6: Sell | E6: Dec17'21 | F6: 10 | H6: 30 | I6: 1.02 | J6: =H6-I6 -> 28.98 | K6: =-(J6-L6) -> -13.62 | L6: 15.36 | M6: Mixed with Butterfly and cancelled out too early
A7: 44524 | B7: LHDX | C7: Call | D7: Sell | E7: Dec17'21 | F7: 7.5 | H7: 30 | I7: 1.02 | J7: =H7-I7 -> 28.98 | K7: 0 | L7: =sum(J7:K7) -> 28.98 | M7: expirred OTM
A8: 44531 | B8: LHDX | C8: Iron butterfly | D8: Sell | E8: Dec17'21 | F8: 5/7.5 | H8: 120 | I8: 2.49 | J8: =H8-I8 -> 117.51 | K8: =(8.02-7.5)*100 -> 52 | L8: =sum(J8:K8) -> 169.51 | M8: Assigned but sold later with profit of 52
A10: 44553 | B10: LHDX | C10: Call | D10: Sell | E10: Jan21'22 | F10: 10 | H10: 50 | I10: 0.16 | J10: =H10-I10 -> 49.84 | K10: 0 | L10: =sum(J10:K10) -> 49.84 | M10: expired OTM | N10: 1.14 | P10: 0.214 | Q10: 0.76 | R10: <1%
A11: 21/12.2021 | B11: LHDX | C11: Call | D11: Sell | E11: Jan21'22 | F11: 7.5 | H11: 74 | I11: 0.17 | J11: =H11-I11 -> 73.83 | K11: 0 | L11: =sum(J11:K11) -> 73.83 | M11: expired OTM | N11: 1.23 | P11: 0.216 | Q11: 0.59 | R11: <1%
A12: 44543 | B12: LHDX | C12: Bull put | E12: Jan21'22 | F12: 2.5/5 | H12: =(0.654-0.111)*2*100 -> 108.6 | I12: =2.1+1.03 -> 3.13 | J12: =H12-I12+(5.215-5)*200 -> 148.47 | K12: 0 | L12: =sum(J12:K12) -> 148.47 | M12: Put assigned. But sold on 01/03 for 5.215 | N12: 1.073 | P12: 0.215 | Q12: 0.53 | R12: 0.023
A13: 21/12.2021 | B13: DBC | C13: Call | D13: Sell | E13: Jan21'22 | F13: 21 | H13: 20 | I13: 0.27 | J13: =H13-I13 -> 19.73 | K13: 0 | L13: =sum(J13:K13) -> 19.73 | M13: Assigned, compensated prevous put. | N13: 0.208 | P13: 0.216 | Q13: 0.77 | R13: <1%
A14: 44553 | B14: PRGO | C14: Call | D14: Sell | E14: Jan21'22 | F14: 42.5 | H14: 30 | I14: 1.02 | J14: =H14-I14 -> 28.98 | K14: 0 | L14: =sum(J14:K14) -> 28.98 | M14: expired OTM
A16: 44594 | B16: VTI | C16: Call | D16: Sell | E16: Feb18'22 | F16: 235 | H16: 110 | I16: 1.89 | J16: =H16-I16 -> 108.11 | K16: 0 | L16: =sum(J16:K16) -> 108.11 | M16: expired OTM | N16: 0.185 | P16: 0.2265 | Q16: 0.73 | R16: <1%
A17: 44595 | B17: ASAN | C17: Put | D17: Sell | E17: Feb18'22 | F17: 40 | H17: 135 | I17: 0.3 | J17: =H17-I17 -> 134.7 | K17: 0 | L17: =sum(J17:K17) -> 134.7 | M17: expired OTM | N17: 0.99 | P17: 0.244 | Q17: 0.75 | R17: <1% | S17: 0.8
A19: 44603 | B19: ASAN | C19: Put | D19: Sell | E19: Mar18'22 | F19: 50 | H19: 321 | I19: 0.2 | J19: =H19-I19 -> 320.8 | M19: Assigned. Paper loss as not sold yet. | N19: 1.068 | P19: 0.2855 | Q19: 0.75 | R19: <1% | S19: 0.81
A20: 44614 | B20: ASAN | C20: Put | D20: Sell | E20: Mar18'22 | F20: 40 | H20: 104 | I20: 0.2 | J20: =H20-I20 -> 103.8 | K20: 0 | L20: =sum(J20:K20) -> 103.8 | M20: expired OTM | N20: 1.11 | P20: 0.2905 | Q20: 0.9 | R20: <1% | S20: 0.91
A21: 44614 | B21: VTI | C21: Call | D21: Sell | E21: Mar18'22 | F21: 230 | H21: 86 | I21: 0.2 | J21: =H21-I21 -> 85.8 | L21: =sum(J21:K21) -> 85.8 | M21: expired OTM | N21: 0.27 | P21: 0.2905 | Q21: 0.82 | R21: <1% | S21: 0.83
A22: 44615 | B22: CROX | C22: Call | D22: Sell | E22: Mar18'22 | F22: 90 | H22: 240 | I22: 0.3 | J22: =H22-I22 -> 239.7 | L22: =sum(J22:K22) -> 239.7 | M22: expired OTM | N22: 0.67 | P22: 0.29 | Q22: 0.73 | R22: <1% | S22: 0.77
A23: 44616 | B23: ASAN | C23: Call | D23: Sell | E23: Mar18'22 | F23: 60 | H23: 336 | I23: 0.2 | J23: =H23-I23 -> 335.8 | L23: =sum(J23:K23) -> 335.8 | M23: expired OTM | N23: 133.2 | P23: 0.31 | Q23: 0.69 | R23: <1% | S23: 0.74
A24: 44620 | B24: LHDX | C24: Call | D24: Sell | E24: Mar18'22 | F24: 5 | H24: 90 | I24: 0.1 | J24: =H24-I24 -> 89.9 | L24: =sum(J24:K24) -> 89.9 | M24: expired OTM | N24: 1.29 | P24: 0.2945 | Q24: 0.54 | R24: <1% | S24: 0.63
A25: 44629 | B25: DBC | C25: Call | D25: Sell | E25: Mar18'22 | F25: 26 | H25: 74 | I25: 0.2 | J25: =H25-I25 -> 73.8 | L25: =sum(J25:K25) -> 73.8 | M25: Sold call as want to re-balance. This is instead of selling DBC directly.
A27: 44634 | B27: CROX | C27: Call | D27: Buy | E27: Jun17'22 | F27: 95 | I27: 0.2 | K27: =-266-I27 -> -266.2 | L27: =sum(J27:K27) -> -266.2 | N27: 0.73 | P27: 0.3255 | S27: 0.17
A28: 44642 | B28: CROX | C28: Call | D28: Sell | E28: Apr14'22 | F28: 85 | H28: 396 | I28: 0.25 | J28: =H28-I28 -> 395.75 | K28: =-7-0.25 -> -7.25 | L28: =sum(J28:K28) -> 388.5 | M28: Closed for $7, 4 days before expiry | N28: 0.59 | P28: 0.2505 | Q28: 0.55 | R28: <1% | S28: 0.67
A29: 44642 | B29: VTI | C29: Call | D29: Sell | E29: Apr14'22 | F29: 235 | H29: 100 | I29: 1.05 | J29: =H29-I29 -> 98.95 | K29: =-5-1.9 -> -6.9 | L29: =sum(J29:K29) -> 92.05 | M29: Closed for $5, 4 days before expiry | N29: 0.19 | P29: 0.2505 | Q29: 0.76 | R29: <1% | S29: 0.79
A30: 44642 | B30: ASAN | C30: Put | D30: Sell | E30: Apr14'22 | F30: 35 | H30: 95 | I30: 1.05 | J30: =H30-I30 -> 93.95 | K30: =(33.36-35)*100 -> -164 | M30: Assigned. Paper loss as not sold yet. | N30: 0.88 | P30: 0.2505 | Q30: 0.82 | R30: <1% | S30: 0.85
A31: 44643 | B31: ASAN | C31: Call | D31: Sell | E31: Apr14'22 | F31: 50 | H31: 156 | I31: 0.2 | J31: =H31-I31 -> 155.8 | K31: =-5-1.9 -> -6.9 | L31: =sum(J31:K31) -> 148.9 | M31: Closed for $5, 4 days before expiry | N31: 0.9 | P31: 0.254 | Q31: 0.73 | R31: <1% | S31: 0.78
A32: 44643 | B32: DBC | C32: Call | D32: Sell | E32: Apr14'22 | F32: 28 | H32: 79 | I32: 0.2 | J32: =H32-I32 -> 78.8 | K32: =-5-0.3 -> -5.3 | L32: =sum(J32:K32) -> 73.5 | M32: Closed for $5, 4 days before expiry | N32: 0.38 | P32: 0.254 | Q32: 0.6 | R32: <1% | S32: 0.7
A34: 44663 | B34: CROX | C34: Put | D34: Sell | E34: May20'22 | F34: 60 | H34: 175 | I34: 1.05 | J34: =H34-I34 -> 173.95 | L34: =sum(J34:K34) -> 173.95 | M34: Assigned but sold in august for 60. | N34: 0.65 | P34: 0.243 | Q34: 0.8 | R34: <1% | S34: 0.83
A35: 44600 | B35: PRGO | C35: Call | D35: Sell | E35: May20'22 | F35: 42.5 | H35: 85 | I35: 0.19 | J35: =H35-I35 -> 84.81 | L35: =sum(J35:K35) -> 84.81 | M35: expired OTM
A36: 44664 | B36: DBC | C36: Call | D36: Sell | E36: May20'22 | F36: 28 | H36: 100 | I36: 1.05 | J36: =H36-I36 -> 98.95 | L36: =sum(J36:K36) -> 98.95 | M36: expired OTM | N36: 0.3 | P36: 0.231 | Q36: 0.52 | R36: <1% | S36: 0.66
A37: 44684 | B37: CROX | C37: Call | D37: Sell | E37: May20'22 | F37: 85 | H37: 129 | I37: 0.25 | J37: =H37-I37 -> 128.75 | L37: =sum(J37:K37) -> 128.75 | M37: expired OTM | N37: 0.81 | P37: 0.294 | Q37: 0.81 | R37: <1% | S37: 0.83
A38: 44684 | B38: ASAN | C38: Put | D38: Sell | E38: May20'22 | F38: 25 | H38: 146 | I38: 0.25 | J38: =H38-I38 -> 145.75 | M38: Assigned. Paper loss as not sold yet. | N38: 1.14 | P38: 0.294 | Q38: 0.65 | R38: <1% | S38: 0.74
A39: 44685 | B39: VTI | C39: Call | D39: Sell | E39: May20'22 | F39: 220 | H39: 100 | I39: 1.05 | J39: =H39-I39 -> 98.95 | L39: =sum(J39:K39) -> 98.95 | M39: expired OTM | N39: 0.26 | P39: 0.28 | Q39: 0.79 | R39: <1% | S39: 0.81
A41: 44705 | B41: PRGO | C41: Call | D41: Sell | E41: Jun17'22 | F41: 37.5 | H41: 151 | I41: 0.25 | J41: =H41-I41 -> 150.75 | K41: 0 | L41: =sum(J41:K41) -> 150.75 | M41: Assigned as planned | N41: 0.31 | P41: 0.28 | Q41: 0.26 | S41: 0.56
A42: 44707 | B42: VTI | C42: Call | D42: Sell | E42: Jun17'22 | F42: 215 | H42: 94 | I42: 1.05 | J42: =H42-I42 -> 92.95 | K42: 0 | L42: =sum(J42:K42) -> 92.95 | M42: expired OTM | N42: 0.26 | P42: 0.28 | Q42: 0.81 | S42: 0.82
A43: 44707 | B43: ASAN | C43: Call | D43: Sell | E43: Jun17'22 | F43: 25 | H43: 171 | I43: 0.21 | J43: =H43-I43 -> 170.79 | K43: 0 | L43: =sum(J43:K43) -> 170.79 | M43: expired OTM | N43: 1.39 | P43: 0.28 | Q43: 0.67 | S43: 0.73
A44: 44707 | B44: CROX | C44: Call | D44: Sell | E44: Jun17'22 | F44: 60 | H44: 141 | I44: 0.25 | J44: =H44-I44 -> 140.75 | K44: 0 | L44: =sum(J44:K44) -> 140.75 | M44: expired OTM | N44: 0.7 | P44: 0.28 | Q44: 0.73 | S44: 0.77
A45: 44707 | B45: DBC | C45: Call | D45: Sell | E45: Jun17'22 | F45: 29 | H45: 50 | I45: 0.55 | J45: =H45-I45 -> 49.45 | K45: 0 | L45: =sum(J45:K45) -> 49.45 | M45: expired OTM | N45: 0.26 | P45: 0.28 | Q45: 0.58 | S45: 0.68
A47: 44755 | B47: CROX | C47: Call | D47: Sell | E47: Aug19'22 | F47: 60 | H47: 296 | I47: 1.91 | J47: =H47-I47 -> 294.09 | L47: =sum(J47:K47) -> 294.09 | M47: assigned and sold as planned to compensate for earlier assignment | N47: 0.78 | P47: 0.27 | Q47: 0.66 | S47: 0.73
A48: 44762 | B48: CROX | C48: Call | D48: Sell | E48: Aug19'22 | F48: 70 | H48: 171 | I48: 1.91 | J48: =H48-I48 -> 169.09 | K48: =-310-1.05 -> -311.05 | L48: =sum(J48:K48) -> -141.96 | M48: closed in advance on drop, as was going up | N48: 0.77 | P48: 0.27 | Q48: 0.75 | S48: 0.79
...

Sheet Options 2023
C1: How Market is doing? | D1: Is option expensive or cheap, should I Sell/Buy? | F1: Volatility ahead? | G1: Liquide? | Q1: =sum(Q3:Q77) -> 7003.14 | X1: @
A2: Trans date | B2: Tiker | C2: VIX | D2: IV | E2: Hist. volatility | F2: Corporate events? | G2: Bid/Ask spread | H2: Type | I2: Action | J2: Expiration | K2: Strike | L2: Qty | M2: Amount | N2: Comission | O2: Total Profit | P2: Total loss | Q2: Total P&L | R2: Comment | S2: Profit probability | T2: Max Win probab | U2: Max Loss | V2: Max Lose probab | W2: Return / Risk
A3: 44930 | B3: ASAN | C3: 0.22 | D3: 0.82 | E3: 0.83 | F3: No | G3: 0.1 | H3: Call | I3: Sell | J3: Feb17'23 | K3: 15 | L3: 4 | M3: 404 | N3: 0.43 | O3: =M3-N3 -> 403.57 | P3: -210.75 | Q3: =sum(O3:P3) -> 192.82 | R3: Closed in one day | S3: 0.71 | T3: 0.63 | U3: infinity | V3: <1% | W3: n/a
A4: 44923 | B4: SPY | C4: 0.215 | D4: 0.206 | E4: 0.198 | F4: No | G4: 0.03 | H4: Bull Put | I4: Sell | J4: Feb17'23 | K4: 353/350 | L4: 10 | M4: 530 | N4: 23.67 | O4: =M4-N4 -> 506.33 | P4: =-127+107-1134+954-23.61 -> -223.61 | Q4: =sum(O4:P4) -> 282.72 | R4: Closed on 10-Jan | S4: 0.83 | T4: 0.82 | U4: 2487 | V4: 0.15 | W4: =Q4/U4 -> 0.11367913
A5: 44923 | B5: GOOGL | C5: 0.2186 | D5: 0.341 | E5: 0.3343 | F5: No | G5: 0.01 | H5: Bull Put | I5: Sell | J5: Jan20'23 | K5: 79.5/77.5 | L5: 10 | M5: 300 | N5: 10.79 | O5: =M5-N5 -> 289.21 | P5: -35.77 | Q5: =sum(O5:P5) -> 253.44 | R5: Closed on 11-Jan | S5: 0.83 | T5: 0.82 | U5: 1719 | V5: 0.11 | W5: =Q5/U5 -> 0.14743455
A6: 44931 | B6: ASAN | C6: 0.22 | D6: 0.874 | E6: 0.848 | F6: No | G6: 0.1 | H6: Bull Put | I6: Sell | J6: Feb17'23 | K6: 10/7.5 | L6: 10 | M6: 440 | N6: 13.8 | O6: =M6-N6 -> 426.2 | P6: -142.71 | Q6: =sum(O6:P6) -> 283.49 | R6: Closed on 13-Jan | S6: 0.77 | T6: 0.73 | U6: 2148 | V6: 0.058 | W6: =Q6/U6 -> 0.13197858
A7: 44938 | B7: GOOGL | C7: 0.2 | D7: 0.376 | E7: 0.341 | F7: Yes 7/02 | G7: 0.05 | H7: Bull Put | I7: Sell | J7: Feb17'23 | K7: 80/75 | L7: 10 | M7: 500 | N7: 23.61 | O7: =M7-N7 -> 476.39 | P7: -128.79 | Q7: =sum(O7:P7) -> 347.6 | R7: Closed on 23-Jan | S7: 0.88 | T7: 0.87 | U7: 4518 | V7: 0.045 | W7: =Q7/U7 -> 0.076936698
A9: 44938 | B9: SPY | C9: 0.2 | D9: 0.18 | E9: 0.2 | F9: No | G9: 0.03 | H9: Bull Put | I9: Sell | J9: Feb17'23 | K9: 376/373 | L9: 10 | M9: 420 | N9: 8.85 | O9: =M9-N9 -> 411.15 | P9: -148.8 | Q9: =sum(O9:P9) -> 262.35 | R9: Closed on 31-Jan | S9: 0.85 | T9: 0.85 | U9: 2578 | V9: 0.12 | W9: =Q9/U9 -> 0.10176493
A10: 44931 | B10: CROX | C10: 0.224 | D10: 0.683 | E10: 0.513 | F10: No | G10: 0.6 | H10: Call | I10: Sell | J10: Feb17'23 | K10: 130 | L10: 1 | M10: 340 | N10: 0.19 | O10: =M10-N10 -> 339.81 | Q10: =sum(O10:P10) -> 339.81 | R10: Assigned but OK to fix profit | S10: 0.79 | T10: 0.76 | U10: infinity | V10: <1% | W10: n/a
A11: 44936 | B11: ASAN | C11: 0.21 | D11: 0.84 | E11: 0.85 | F11: No | G11: 0.1 | H11: Call | I11: Sell | J11: Feb17'23 | K11: 15 | L11: 4 | M11: 280 | N11: 0.67 | O11: =M11-N11 -> 279.33 | Q11: =sum(O11:P11) -> 279.33 | R11: Assigned as planned | S11: 0.73 | T11: 0.66 | U11: infinity | V11: <1% | W11: n/a
A12: 44949 | B12: ASAN | C12: 0.1991 | D12: 0.765 | E12: 0.759 | F12: No | G12: 0.1 | H12: Call | I12: Sell | J12: Feb17'23 | K12: 16 | L12: 6 | M12: 306 | N12: 9.25 | O12: =M12-N12 -> 296.75 | Q12: =sum(O12:P12) -> 296.75 | R12: Expired OTM | S12: 0.75 | T12: 0.7 | U12: infinity | V12: <1% | W12: n/a
A13: 44971 | B13: SPY | C13: 0.19 | D13: 0.17 | E13: 0.18 | F13: No | G13: 0.01 | H13: Bear call | I13: Sell | J13: Mar17'23 | K13: 431/433 | L13: 10 | M13: 370 | N13: 23.85 | O13: =M13-N13 -> 346.15 | P13: -129.01 | Q13: =sum(O13:P13) -> 217.14 | R13: Closed on 17/02 to take profit | S13: 0.81 | T13: 0.8 | U13: 1629 | V13: 0.17 | W13: =Q13/U13 -> 0.1332965
A15: 44971 | B15: GOOGL | C15: 0.19 | D15: 0.33 | E15: 0.43 | F15: No | G15: 0.1 | H15: Bull Put | I15: Sell | J15: Mar17'23 | K15: 85/83 | L15: 10 | M15: 260 | N15: 13.91 | O15: =M15-N15 -> 246.09 | P15: -34.51 | Q15: =sum(O15:P15) -> 211.58 | R15: Closed on 8/3/2023 | S15: 0.85 | T15: 0.84 | U15: 1739 | V15: 0.11 | W15: =Q15/U15 -> 0.12166763
A16: 44978 | B16: SPY | C16: 0.229 | D16: 0.203 | E16: 0.17671 | F16: No | G16: 0.02 | H16: Bear call | I16: Sell | J16: Mar17'23 | K16: 418/420 | L16: 10 | M16: 360 | N16: 9.04 | O16: =M16-N16 -> 350.96 | P16: -108.17 | Q16: =sum(O16:P16) -> 242.79 | R16: Closed on 2/3/2023
A17: 44992 | B17: SPY | C17: 0.2 | D17: 0.18 | E17: 0.171 | F17: No | G17: 0.01 | H17: Bear call | I17: Sell | J17: Apr21'23 | K17: 420/422 | L17: 10 | M17: 380 | N17: 10.02 | O17: =M17-N17 -> 369.98 | P17: -143.51 | Q17: =sum(O17:P17) -> 226.47 | R17: Closed on 16/3/2023 | S17: 0.79 | T17: 0.79 | U17: 1628 | V17: 0.19 | W17: =Q17/U17 -> 0.13910934
A18: 44978 | B18: CROX | C18: 0.229 | D18: 0.541 | E18: 0.535 | F18: No | G18: 0.4 | H18: Put | I18: Sell | J18: Mar17'23 | K18: 120 | L18: 1 | M18: 591 | N18: 0.27 | O18: =M18-N18 -> 590.73 | Q18: =sum(O18:P18) -> 590.73 | R18: Assigned, bough as planned | S18: 0.67 | T18: 0.53 | U18: 11408 | V18: <1% | W18: 0.05
A19: 44978 | B19: ASAN | C19: 0.229 | D19: 1.131 | E19: 0.8378 | F19: Yes (8/03) | G19: 0.1 | H19: Call | I19: Sell | J19: Mar17'23 | K19: 16 | L19: 6 | M19: 666 | N19: 9.32 | O19: =M19-N19 -> 656.68 | Q19: =sum(O19:P19) -> 656.68 | R19: Assigned, sold to fix profit from previous assignment
A20: 44980 | B20: AAPL | C20: 0.22 | D20: 0.277 | E20: 0.28 | F20: No | G20: 0.05 | H20: Put | I20: Sell | J20: Apr21'23 | K20: 135 | L20: 1 | M20: 215 | N20: 1.05 | O20: =M20-N20 -> 213.95 | P20: -44.85 | Q20: =sum(O20:P20) -> 169.1 | R20: Closed on 23/03/2023 | S20: 0.85 | T20: 0.82 | U20: 13287 | V20: <1% | W20: =Q20/U20 -> 0.012726725
A22: 45001 | B22: C | C22: 0.234 | D22: 0.4 | E22: 0.353 | F22: Yes 13/04 | G22: 0.03 | H22: Put | I22: Sell | J22: Apr21'23 | K22: 45 | L22: 1 | M22: 203 | N22: 0.63 | O22: =M22-N22 -> 202.37 | Q22: =COUNT(Q15:Q21) -> 6 | R22: Ready to buy @45 | S22: 0.68 | T22: 0.54 | U22: 4295 | V22: <1% | W22: =Q22/U22 -> 0.0013969732
A23: 45009 | B23: ASAN | C23: 0.243 | D23: 0.721 | E23: 0.854 | F23: No | G23: 0.1 | H23: Put | I23: Sell | J23: Apr21'23 | K23: 20 | L23: 3 | M23: 453 | N23: 0.29 | O23: =M23-N23 -> 452.71 | Q23: =sum(O23:P23) -> 452.71 | R23: Ready to buy @20. Assigned but OK | S23: 0.67 | T23: 0.53 | U23: 5578 | V23: <1% | W23: =Q23/U23 -> 0.081159914
A24: 45009 | B24: AAPL | C24: 0.223 | D24: 0.292 | E24: 0.242 | F24: Yes | G24: 0.1 | H24: Put | I24: Sell | J24: May19'23 | K24: 145 | L24: 1 | M24: 274 | N24: 1.05 | O24: =M24-N24 -> 272.95 | P24: -53.05 | Q24: =sum(O24:P24) -> 219.9 | R24: Ready to buy @145 | S24: 0.86 | T24: 0.82 | U24: 14234 | V24: <1% | W24: =Q24/U24 -> 0.015448925
A26: 45006 | B26: CROX | H26: Call | I26: Sell | J26: May19'23 | K26: 130 | L26: 1 | M26: 640 | N26: 0.2 | O26: =M26-N26 -> 639.8 | P26: =-156.32-38.25 -> -194.57 | Q26: =sum(O26:P26) -> 445.23 | R26: Ready to sell @125, rolled over to next month at 130 due to high growth. Closed 4/05/2023
A27: 45050 | B27: CROX | C27: 0.2 | D27: 0.556 | E27: 0.548 | F27: No | G27: 0.3 | H27: Put | I27: Sell | J27: May19'23 | K27: 100 | L27: 1 | M27: 164 | N27: 0.25 | O27: =M27-N27 -> 163.75 | P27: -34.25 | Q27: =sum(O27:P27) -> 129.5 | R27: Closed on 8/5/2023 | S27: 0.84 | T27: 0.8 | U27: 9840 | V27: <1% | W27: =Q27/U27 -> 0.013160569
A28: 45048 | B28: AAPL | C28: 0.1806 | D28: 0.259 | E28: 0.187 | F28: Yes | G28: 0.1 | H28: Put | I28: Sell | J28: Jun16'23 | K28: 155 | L28: 1 | M28: 214 | N28: 1.04 | O28: =M28-N28 -> 212.96 | P28: =-78.04 -> -78.04 | Q28: =sum(O28:P28) -> 134.92 | R28: Ready to buy @155 | S28: 0.89 | T28: 0.86 | U28: 15318 | V28: <1% | W28: =Q28/U28 -> 0.0088079384
A29: 44993 | B29: GOOGL | C29: 0.2 | D29: 0.3 | E29: 0.4 | F29: No | G29: 0.1 | H29: Iron condor | I29: Sell | J29: May19'23 | K29: 80/85 105/110 | L29: 5 | M29: 495 | N29: =6.37+0.75*3+0.25+3.25+1.25+1.05+0.62+0.63+0.7+0.71+0.31+0.32+0.04+0.03+0.07 -> 17.85 | O29: =M29-N29+5*5+-908-227-206+882-103*3+441*3 -> 1057.15 | P29: =-256.91-6997.25+4902.7 -> -2351.46 | Q29: =sum(O29:P29) -> -1294.31 | R29: Rolled over to May, bull put expired, rolled to 106/110 | S29: 0.73 | T29: 0.68 | U29: 2007 | V29: 0.14 | W29: =Q29/U29 -> -0.64489786
A30: 45008 | B30: SPY | C30: 0.243 | D30: 0.198 | E30: 0.1867 | F30: No | G30: 0.02 | H30: Bear call | I30: Sell | J30: May19'23 | K30: 411/413 | L30: 10 | M30: 610 | N30: =11.76+1.75*2+1.8*2+9.54+9.51++0.84*2+1.54*2 -> 42.67 | O30: =M30-N30-1870*2+4770*2+1440-6008+180-751+182-753+1017 -> 1674.33 | P30: =-1450-5.97-5.95-4.43-4.41-1.54-1.54-1624 -> -3097.84 | Q30: =sum(O30:P30) -> -1423.51 | R30: Mistake with closing too early as was showing profit when it was not.
A31: 45043 | B31: SPY | C31: 0.187 | D31: 0.134 | E31: 0.1354 | F31: No | G31: 0.01 | H31: Bull put | I31: Sell | J31: May19'23 | K31: 397/395 | L31: 10 | M31: 310 | N31: 20.76 | O31: =M31-N31 -> 289.24 | Q31: =sum(O31:P31) -> 289.24 | S31: 0.92 | T31: 0.92 | U31: 1819 | V31: 0.057 | W31: =Q31/U31 -> 0.15901045
A33: 45055 | B33: SPY | C33: 0.17 | D33: 0.153 | E33: 0.114 | F33: No | G33: 0.01 | H33: Bear call | I33: Sell | J33: Jun16'23 | K33: 427/429 | L33: 10 | M33: 470 | N33: =21.66+23.83 -> 45.49 | O33: =M33-N33+850+899+665.93+561.4 -> 3400.84 | P33: =-1153.83-1034-1147.65-1101.26-1531.26 -> -5968 | Q33: =sum(O33:P33) -> -2567.16 | R33: Moving to higher levels | S33: 0.76 | T33: 0.75 | U33: 1527 | V33: 0.22 | W33: =Q33/U33 -> -1.6811788
A34: 45055 | B34: SPY | C34: 0.17 | D34: 0.153 | E34: 0.114 | F34: No | G34: 0.01 | H34: Bull put | I34: Sell | J34: Jun16'23 | K34: 391/389 | L34: 10 | M34: 280 | N34: =23.86+21.86 -> 45.72 | O34: =M34-N34+270+172+226.19+227.63+196.19 -> 1326.29 | P34: -58.01 | Q34: =sum(O34:P34) -> 1268.28 | R34: Moving to higher levels 418/416, 421/419, 424/422 | S34: 0.86 | T34: 0.86 | U34: 1739 | V34: 0.12 | W34: =Q34/U34 -> 0.7293157
A35: 45057 | B35: CROX | C35: 0.17 | D35: 0.468 | E35: 0.542 | F35: No | G35: 0.2 | H35: Bull put | I35: Sell | J35: Jun16'23 | K35: 105 | L35: 1 | M35: 269 | N35: 0.25 | O35: =M35-N35 -> 268.75 | Q35: =sum(O35:P35) -> 268.75 | S35: 0.82 | T35: 0.77 | U35: 10234 | V35: <1% | W35: =Q35/U35 -> 0.026260504
A36: 45063 | B36: ASAN | C36: 0.17 | D36: 0.788 | E36: 0.516 | F36: Yes | G36: 0.15 | H36: Call | I36: Sell | J36: Jun16'23 | K36: 20 | L36: 3 | M36: 420 | N36: 0.14 | O36: =M36-N36 -> 419.86 | Q36: =sum(O36:P36) -> 419.86 | R36: Assigned but OK | S36: 0.68 | T36: 0.57
A37: 45071 | B37: GOOGL | C37: 0.19 | D37: 0.287 | E37: 0.315 | F37: No | G37: 0.1 | H37: Call | I37: Sell | J37: Jun16'23 | K37: 130 | L37: 1 | M37: 127 | N37: 1.04 | O37: =M37-N37 -> 125.96 | Q37: =sum(O37:P37) -> 125.96 | S37: 0.79 | T37: 0.75
A39: 45097 | B39: CROX | C39: 0.14 | D39: 0.47 | E39: 0.44 | F39: No | G39: 0.2 | H39: Put | I39: Sell | J39: Jul21'23 | K39: 105 | L39: 1 | M39: 496 | N39: 0.26 | O39: =M39-N39 -> 495.74 | P39: -9.05 | Q39: =sum(O39:P39) -> 486.69 | S39: 0.68 | T39: 0.55 | U39: 9998 | V39: <1% | W39: 0.05
A40: 45097 | B40: GOOGL | C40: 0.14 | D40: 0.24 | E40: 0.29 | F40: No | G40: 0.05 | H40: Put | I40: Sell | J40: Jul21'23 | K40: 120 | L40: 1 | M40: 196 | N40: 0.63 | O40: =M40-N40 -> 195.37 | P40: -23.46 | Q40: =sum(O40:P40) -> 171.91 | S40: 0.75 | T40: 0.67 | U40: 11803 | V40: <1% | W40: 0.02
A41: 45097 | B41: ASAN | C41: 0.15 | D41: 0.59 | E41: 0.68 | F41: No | G41: 0.1 | H41: Call | I41: Sell | J41: Jul21'23 | K41: 25 | L41: 1 | M41: 131 | N41: 1.9 | O41: =M41-N41 -> 129.1 | P41: -18.05 | Q41: =sum(O41:P41) -> 111.05 | S41: 0.68 | T41: 0.57 | V41: <1%
A43: 45121 | B43: GOOGL | C43: 0.14 | D43: 0.3 | E43: 0.26 | F43: Yes | G43: 0.1 | H43: Call | I43: Sell | J43: Aug18'23 | K43: 130 | L43: 1 | M43: 297 | N43: 0.63 | O43: =M43-N43 -> 296.37 | Q43: =sum(O43:P43) -> 296.37 | R43: Expired OTM | S43: 0.72 | T43: 0.63 | V43: <1%
A44: 45121 | B44: CROX | C44: 0.14 | D44: 0.6 | E44: 0.41 | F44: No | G44: 0.3 | H44: Call | I44: Sell | J44: Aug18'23 | K44: 135 | L44: 1 | M44: 541 | N44: 0.26 | O44: =M44-N44 -> 540.74 | P44: -15.05 | Q44: =sum(O44:P44) -> 525.69 | R44: Closed on 27/07 | S44: 0.73 | T44: 0.66 | V44: <1%
A45: 45124 | B45: AAPL | C45: 0.137 | D45: 0.216 | E45: 0.172 | F45: No | G45: 0.05 | H45: Put | I45: Sell | J45: Aug18'23 | K45: 180 | L45: 1 | M45: 111 | N45: 1.04 | O45: =M45-N45 -> 109.96 | Q45: =sum(O45:P45) -> 109.96 | R45: Assigned | S45: 0.91 | T45: 0.89 | U45: 17811 | V45: <1% | W45: 0.01
A46: 45124 | B46: SPY | C46: 0.137 | D46: 0.11 | E46: 0.1 | F46: No | G46: 0.01 | H46: Bear call | I46: Sell | J46: Aug18'23 | K46: 466/468 | L46: 10 | M46: 340 | N46: 23.82 | O46: =M46-N46 -> 316.18 | P46: -134.03 | Q46: =sum(O46:P46) -> 182.15 | R46: Closed on 3/08 | S46: 0.8 | T46: 0.79 | U46: 1651 | V46: 0.17 | W46: =O46/U46 -> 0.19150818
A47: 45134 | B47: CROX | C47: 0.1575 | D47: 0.465 | E47: 0.65 | F47: Yes | G47: 0.3 | H47: Put | I47: Sell | J47: Aug18'23 | K47: 95 | L47: 1 | M47: 169 | N47: 0.25 | O47: =M47-N47 -> 168.75 | Q47: =sum(O47:P47) -> 168.75 | R47: Assigned | S47: 0.92 | U47: 9412 | W47: 0.01
...

Sheet Options 2024
C1: How Market is doing? | D1: Is option expensive or cheap, should I Sell/Buy? | F1: Volatility ahead? | G1: Liquide? | Q1: =sum(Q3:Q78) -> 11948.69 | Y1: @
A2: Trans date | B2: Tiker | C2: VIX | D2: IV | E2: Hist. volatility | F2: Corporate events? | G2: Bid/Ask spread | H2: Type | I2: Action | J2: Expiration | K2: Strike | L2: Qty | M2: Amount | N2: Comission | O2: Total Profit | P2: Total loss | Q2: Total P&L | R2: Comment | S2: Profit % | T2: Profit probability | U2: Max Win probab | V2: Max Loss | W2: Max Lose probab | X2: Return / Risk | Y2: Assigned
A3: 45313 | B3: GOOGL | C3: 0.13 | D3: 0.31 | E3: 0.25 | F3: Yes | G3: 0.05 | H3: Put | I3: Sell | J3: 16.02.2024 | K3: 140 | L3: 1 | M3: 208 | N3: 0.63 | O3: =M3-N3 -> 207.37 | Q3: =sum(O3:P3) -> 207.37 | R3: Expired OOM | S3: =O3/(L3*100)/K3 -> 0.014812143 | T3: 0.78 | U3: 0.72 | V3: 13736 | W3: <1% | X3: 0.02 | Z3: =K3*L3*100 -> 14000
A4: 45313 | B4: AAPL | C4: 0.13 | D4: 0.23 | E4: 0.2 | F4: Yes | G4: 0.01 | H4: Call | I4: Sell | J4: 16.02.2024 | K4: 200 | L4: 1 | M4: 225 | N4: 1.04 | O4: =M4-N4 -> 223.96 | Q4: =sum(O4:P4) -> 223.96 | R4: Expired OOM | S4: =O4/(L4*100)/K4 -> 0.011198 | T4: 0.75 | U4: 0.68 | Z4: =K4*L4*100 -> 20000
A5: 45314 | B5: CROX | C5: 0.13 | D5: 0.46 | E5: 0.52 | F5: Yes | G5: 0.5 | H5: Call | I5: Sell | J5: 16.02.2024 | K5: 110 | L5: 2 | M5: 362 | N5: 0.7 | O5: =M5-N5 -> 361.3 | Q5: =sum(O5:P5) -> 361.3 | R5: Assigned | S5: =O5/(L5*100)/K5 -> 0.016422727 | T5: 0.78 | U5: 0.74 | Y5: 1 | Z5: =K5*L5*100 -> 22000
A6: 45322 | B6: ASAN | C6: 0.14 | D6: 0.54 | E6: 0.42 | F6: No | G6: 0.1 | H6: Put | I6: Sell | J6: 16.02.2024 | K6: 17.5 | L6: 4 | M6: 224 | N6: 6.2 | O6: =M6-N6 -> 217.8 | Q6: =sum(O6:P6) -> 217.8 | R6: Expired OOM | S6: =O6/(L6*100)/K6 -> 0.031114286 | T6: 0.69 | U6: 0.58 | V6: 6763 | W6: <1% | X6: 0.03 | Z6: =K6*L6*100 -> 7000
Z7: =sum(Z3:Z6) -> 63000 | AA7: =sum(Q3:Q6)/Z7 -> 0.016038571
A8: 45342 | B8: AAPL | C8: 0.1553 | D8: 0.21 | E8: 0.22 | F8: No | G8: 0.05 | H8: Put | I8: Sell | J8: 15.03.2024 | K8: 170 | L8: 1 | M8: 87 | N8: 1.04 | O8: =M8-N8 -> 85.96 | Q8: =sum(O8:P8) -> 85.96 | R8: Expired | S8: =O8/(L8*100)/K8 -> 0.0050564706 | T8: 0.89 | U8: 0.87 | V8: 16853 | W8: <1% | X8: 0.01 | Z8: =K8*L8*100 -> 17000
A9: 45342 | B9: ASAN | C9: 0.1553 | D9: 0.845 | E9: 0.486 | F9: No | G9: 0.05 | H9: Put | I9: Sell | J9: 15.03.2024 | K9: 17.5 | L9: 2 | M9: 212 | N9: 0.7 | O9: =M9-N9 -> 211.3 | Q9: =sum(O9:P9) -> 211.3 | R9: Assigned | S9: =O9/(L9*100)/K9 -> 0.060371429 | T9: 0.72 | U9: 0.61 | V9: 3278 | W9: <1% | X9: 0.06 | Y9: 1 | Z9: =K9*L9*100 -> 3500
A10: 45342 | B10: GOOGL | C10: 0.1553 | D10: 0.248 | E10: 0.274 | F10: No | G10: 0.02 | H10: Put | I10: Sell | J10: 15.03.2024 | K10: 138 | L10: 1 | M10: 219 | N10: 1.04 | O10: =M10-N10 -> 217.96 | Q10: =sum(O10:P10) -> 217.96 | R10: Expired | S10: =O10/(L10*100)/K10 -> 0.015794203 | T10: 0.74 | U10: 0.65 | V10: 13534 | W10: <1% | X10: 0.02 | Z10: =K10*L10*100 -> 13800
A11: 45342 | B11: AAPL | C11: 0.1553 | D11: =D8 -> 0.21 | E11: =E8 -> 0.22 | F11: No | G11: 0.05 | H11: Call | I11: Sell | J11: 15.03.2024 | K11: 190 | L11: 1 | M11: 105 | N11: 0.53 | O11: =M11-N11 -> 104.47 | Q11: =sum(O11:P11) -> 104.47 | R11: Expired | S11: =O11/(L11*100)/K11 -> 0.0054984211 | T11: 0.83 | U11: 0.8 | Z11: =K11*L11*100 -> 19000
A12: 45342 | B12: CROX | C12: 0.1553 | D12: 0.385 | E12: 0.606 | F12: No | G12: 0.1 | H12: Put | I12: Sell | J12: 15.03.2024 | K12: 110 | L12: 2 | M12: =452+258.2 -> 710.2 | N12: 0.7 | O12: =M12-N12 -> 709.5 | P12: -49.44 | Q12: =sum(O12:P12) -> 660.06 | R12: Expired | S12: =O12/(L12*100)/K12 -> 0.03225 | T12: 0.76 | U12: 0.69 | V12: 21462 | W12: <1% | X12: 0.02 | Z12: =K12*L12*100 -> 22000
A13: 45343 | B13: ASAN | C13: 0.1581 | D13: 0.855 | E13: 0.51 | F13: No | G13: 0.1 | H13: Put | I13: Sell | J13: 15.03.2024 | K13: 17 | L13: 2 | M13: 232 | N13: 0.7 | O13: =M13-N13 -> 231.3 | Q13: =sum(O13:P13) -> 231.3 | R13: Assigned | S13: =O13/(L13*100)/K13 -> 0.068029412 | T13: 0.69 | U13: 0.57 | V13: 3158 | W13: <1% | X13: 0.07 | Y13: 1 | Z13: =K13*L13*100 -> 3400
Z14: =sum(Z8:Z13) -> 78700 | AA14: =sum(Q8:Q13)/Z14 -> 0.019200127
A15: 45370 | B15: GOOGL | C15: 0.14 | D15: 0.24 | E15: 0.28 | F15: No | G15: 0.05 | H15: Put | I15: Sell | J15: 19.04.2024 | K15: 140 | L15: 1 | M15: 136 | N15: 1.04 | O15: =M15-N15 -> 134.96 | P15: -27.05 | Q15: =sum(O15:P15) -> 107.91 | R15: Closed ahead | S15: =O15/(L15*100)/K15 -> 0.00964
A16: 45370 | B16: CROX | C16: 0.14 | D16: 0.35 | E16: 0.44 | F16: No | G16: 0.2 | H16: Put | I16: Sell | J16: 19.04.2024 | K16: 120 | L16: 1 | M16: 131 | N16: 0.25 | O16: =M16-N16 -> 130.75 | P16: -22.05 | Q16: =sum(O16:P16) -> 108.7 | R16: Closed ahead | S16: =O16/(L16*100)/K16 -> 0.010895833
A17: 45370 | B17: ASAN | C17: 0.14 | D17: 0.46 | E17: 0.52 | F17: No | G17: 0.1 | H17: Put | I17: Sell | J17: 19.04.2024 | K17: 15 | L17: 4 | M17: 184 | N17: 6.2 | O17: =M17-N17 -> 177.8 | Q17: =sum(O17:P17) -> 177.8 | R17: Put assigned | S17: =O17/(L17*100)/K17 -> 0.029633333 | Y17: 1 | Z17: =K17*L17*100 -> 6000
A18: 45372 | B18: AAPL | C18: 0.13 | D18: 0.22 | E18: 0.22 | F18: No | G18: 0.03 | H18: Put | I18: Sell | J18: 19.04.2024 | K18: 167.5 | L18: 1 | M18: 246 | N18: 0.63 | O18: =M18-N18 -> 245.37 | Q18: =sum(O18:P18) -> 245.37 | R18: Put assigned | S18: =O18/(L18*100)/K18 -> 0.014648955 | Y18: 1 | Z18: =K18*L18*100 -> 16750
A19: 45385 | B19: CROX | C19: 0.14 | D19: 0.35 | E19: 0.3 | F19: No | G19: 0.05 | H19: Put | I19: Sell | J19: 19.04.2024 | K19: 135 | L19: 1 | M19: 244 | O19: =M19-N19 -> 244 | Q19: =sum(O19:P19) -> 244 | R19: Put assigned | S19: =O19/(L19*100)/K19 -> 0.018074074 | Y19: 1 | Z19: =K19*L19*100 -> 13500
A20: 45385 | B20: GOOGL | C20: 0.14 | D20: 0.25 | E20: 0.27 | F20: No | G20: 0.03 | H20: Put | I20: Sell | J20: 19.04.2024 | K20: 150 | L20: 1 | M20: 143 | N20: 1.05 | O20: =M20-N20 -> 141.95 | Q20: =sum(O20:P20) -> 141.95 | R20: Expired OOM | S20: =O20/(L20*100)/K20 -> 0.0094633333 | Z20: =K20*L20*100 -> 15000
A21: 45407 | B21: GOOGL | C21: 0.166 | D21: 1.21 | E21: 0.3 | F21: Yes | G21: 0.04 | H21: Call | I21: Sell | J21: 19.04.2024 | K21: 150 | L21: 1 | M21: 219 | N21: 1.05 | O21: =M21-N21 -> 217.95 | Q21: =sum(O21:P21) -> 217.95 | R21: Expired OOM | S21: =O21/(L21*100)/K21 -> 0.01453 | T21: 0.76 | U21: 0.7 | Z21: =K21*L21*100 -> 15000
Z22: =sum(Z16:Z21) -> 66250 | AA22: =sum(Q15:Q21)/Z22 -> 0.018772528
A23: 45407 | B23: AAPL | C23: 0.166 | D23: 0.289 | E23: 0.197 | F23: Yes | G23: 0.03 | H23: Call | I23: Sell | J23: 17.05.2024 | K23: 175 | L23: 1 | M23: 280 | N23: 1.04 | O23: =M23-N23 -> 278.96 | Q23: =sum(O23:P23) -> 278.96 | R23: Call assigned | S23: =O23/(L23*100)/K23 -> 0.015940571 | T23: 0.73 | U23: 0.65 | Y23: 1 | Z23: =K23*L23*100 -> 17500
A24: 45408 | B24: CROX | C24: 0.15 | D24: 0.61 | E24: 0.36 | F24: Yes | G24: 0.15 | H24: Call | I24: Sell | J24: 17.05.2024 | K24: 140 | L24: 1 | M24: 250 | N24: 0.05 | O24: =M24-N24 -> 249.95 | Q24: =sum(O24:P24) -> 249.95 | R24: Call assigned | S24: =O24/(L24*100)/K24 -> 0.017853571 | T24: 0.8 | U24: 0.77 | Y24: 1 | Z24: =K24*L24*100 -> 14000
A25: 45411 | B25: ASAN | C25: 0.15 | D25: 0.48 | E25: 0.39 | F25: No | G25: 0.05 | H25: Call | I25: Sell | J25: 17.05.2024 | K25: 15.5 | L25: 4 | M25: 216 | N25: 1.4 | O25: =M25-N25 -> 214.6 | Q25: =sum(O25:P25) -> 214.6 | R25: Call assigned | S25: =O25/(L25*100)/K25 -> 0.034612903 | T25: 0.66 | U25: 0.55 | Y25: 1 | Z25: =K25*L25*100 -> 6200
A26: 45411 | B26: GOOGL | C26: 0.15 | D26: 0.28 | E26: 0.45 | F26: No | G26: 0.04 | H26: Put | I26: Sell | J26: 17.05.2024 | K26: 160 | L26: 1 | M26: 164 | N26: 1.04 | O26: =M26-N26 -> 162.96 | Q26: =sum(O26:P26) -> 162.96 | R26: Expired OOM | S26: =O26/(L26*100)/K26 -> 0.010185 | T26: 0.8 | U26: 0.75 | Z26: =K26*L26*100 -> 16000
Z27: =sum(Z23:Z26) -> 53700 | AA27: =sum(Q23:Q26)/Z27 -> 0.016880261
A28: 45436 | B28: CROX | C28: 0.12 | D28: 0.3 | E28: 0.41 | F28: No | G28: 0.2 | H28: Put | I28: Sell | J28: 21.06.2024 | K28: 140 | L28: 1 | M28: 150 | N28: 0.05 | O28: =M28-N28 -> 149.95 | Q28: =sum(O28:P28) -> 149.95 | S28: =O28/(L28*100)/K28 -> 0.010710714 | T28: 0.82 | U28: 0.79 | V28: 13799 | X28: 0.01 | Z28: =K28*L28*100 -> 14000
A29: 45436 | B29: ASAN | C29: 0.12 | D29: 0.79 | E29: 0.42 | F29: Yes | G29: 0.1 | H29: Put | I29: Sell | J29: 21.06.2024 | K29: 14.5 | L29: 4 | M29: 492 | N29: 1.39 | O29: =M29-N29 -> 490.61 | P29: =-472-1.41 -> -473.41 | Q29: =sum(O29:P29) -> 17.2 | R29: closed to avoid losses | S29: =O29/(L29*100)/K29 -> 0.084587931 | T29: 0.66 | U29: 0.5 | V29: 5277 | X29: 0.09
A30: 45436 | B30: GOOGL | C30: 0.12 | D30: 0.21 | E30: 0.43 | F30: No | G30: 0.05 | H30: Put | I30: Sell | J30: 21.06.2024 | K30: 170 | L30: 1 | M30: 193 | N30: 1.05 | O30: =M30-N30 -> 191.95 | Q30: =sum(O30:P30) -> 191.95 | S30: =O30/(L30*100)/K30 -> 0.011291176 | T30: 0.76 | U30: 0.7 | V30: 16756 | X30: 0.01 | Z30: =K30*L30*100 -> 17000
A31: 45447 | B31: AAPL | C31: 0.136 | D31: 0.23 | E31: 0.29 | F31: No | G31: 0.03 | H31: Call | I31: Sell | J31: 21.06.2024 | K31: 202.5 | L31: 1 | M31: 140 | N31: 1.05 | O31: =M31-N31 -> 138.95 | Q31: =sum(O31:P31) -> 138.95 | R31: Call assigned | S31: =O31/(L31*100)/K31 -> 0.0068617284 | T31: 0.8 | U31: 0.76 | Y31: 1 | Z31: =K31*L31*100 -> 20250
A32: 45447 | B32: ASAN | C32: 0.136 | D32: 0.45 | E32: 0.65 | F32: No | G32: 0.05 | H32: Call | I32: Sell | J32: 21.06.2024 | K32: 14.5 | L32: 4 | M32: 136 | N32: 1.4 | O32: =M32-N32 -> 134.6 | Q32: =sum(O32:P32) -> 134.6 | S32: =O32/(L32*100)/K32 -> 0.023206897 | T32: 0.85 | Z32: =K32*L32*100 -> 5800
Z33: =sum(Z28:Z32) -> 57050 | AA33: =sum(Q28:Q32)/Z33 -> 0.011089395
A34: 45460 | B34: CROX | C34: 0.13 | D34: 0.33 | E34: 0.4 | F34: No | G34: 0.2 | H34: Put | I34: Sell | J34: 19.07.2024 | K34: 150 | L34: 1 | M34: 211 | N34: 0.01 | O34: =M34-N34 -> 210.99 | Q34: =sum(O34:P34) -> 210.99 | R34: Assigned | S34: =O34/(L34*100)/K34 -> 0.014066 | T34: 0.82 | U34: 0.78 | V34: 14724 | X34: 0.01 | Y34: 1 | Z34: =K34*L34*100 -> 15000
A35: 45467 | B35: AAPL | C35: 0.13 | D35: 0.2 | E35: 0.23 | F35: No | H35: Put | I35: Sell | J35: 19.07.2024 | K35: 202.5 | L35: 1 | M35: 170 | N35: 1.04 | O35: =M35-N35 -> 168.96 | P35: -46.8 | Q35: =sum(O35:P35) -> 122.16 | R35: Closed in advance to book profit | S35: =O35/(L35*100)/K35 -> 0.0083437037 | T35: 0.79 | U35: 0.75 | V35: 20001 | X35: 0.01
A36: 45467 | B36: GOOGL | C36: 0.13 | D36: 0.21 | E36: 0.2 | F36: No | G36: 0.05 | H36: Put | I36: Sell | J36: 19.07.2024 | K36: 172.5 | L36: 1 | M36: 144 | N36: 0.8 | O36: =M36-N36 -> 143.2 | P36: -28.46 | Q36: =sum(O36:P36) -> 114.74 | R36: Closed in advance to book profit | S36: =O36/(L36*100)/K36 -> 0.0083014493 | T36: 0.81 | U36: 0.76 | V36: 17042 | X36: 0.01
A37: 45467 | B37: ASAN | C37: 0.13 | D37: 0.47 | E37: 0.66 | F37: No | G37: 0.1 | H37: Put | I37: Sell | J37: 19.07.2024 | K37: 12.5 | L37: 4 | M37: 216 | N37: 1.4 | O37: =M37-N37 -> 214.6 | Q37: =sum(O37:P37) -> 214.6 | S37: =O37/(L37*100)/K37 -> 0.04292 | T37: 0.66 | U37: 0.53 | V37: 4781 | X37: 0.04 | Z37: =K37*L37*100 -> 5000
A38: 45474 | B38: AAPL | C38: 0.12 | D38: 0.2 | E38: 0.23 | F38: No | G38: 0.03 | H38: Put | I38: Sell | J38: 19.07.2024 | K38: 210 | L38: 1 | M38: 157 | N38: 1.04 | O38: =M38-N38 -> 155.96 | P38: -10.5 | Q38: =sum(O38:P38) -> 145.46 | R38: Closed in advance to book profit | S38: =O38/(L38*100)/K38 -> 0.0074266667 | T38: 0.79 | U38: 0.74 | V38: 20786
A39: 45475 | B39: GOOGL | C39: 0.12 | D39: 0.19 | E39: 0.19 | F39: No | G39: 0.04 | H39: Put | I39: Sell | J39: 19.07.2024 | K39: 180 | L39: 1 | M39: 118 | N39: 0.8 | O39: =M39-N39 -> 117.2 | Q39: =sum(O39:P39) -> 117.2 | R39: Assigned | S39: =O39/(L39*100)/K39 -> 0.0065111111 | T39: 0.81 | U39: 0.77 | V39: 17846 | X39: 0.01 | Y39: 1 | Z39: =K39*L39*100 -> 18000
A40: 45485 | B40: AAPL | C40: 0.12 | D40: 0.2 | E40: 0.24 | F40: No | G40: 0.03 | H40: Put | I40: Sell | J40: 19.07.2024 | K40: 227.5 | L40: 1 | M40: 139 | N40: 1.05 | O40: =M40-N40 -> 137.95 | Q40: =sum(O40:P40) -> 137.95 | R40: Assigned | S40: =O40/(L40*100)/K40 -> 0.0060637363 | T40: 0.82 | U40: 0.78 | V40: 22636 | X40: 0 | Y40: 1 | Z40: =K40*L40*100 -> 22750
...

Sheet Options 2025
Q1: =sum(Q3:Q979) -> 23955.13
A2: Trans date | B2: Tiker | C2: VIX | D2: IV (>30%) | E2: Hist. vol. | F2: Corporate events? | G2: Bid/Ask spread | H2: Type | I2: Action | J2: Expiration | K2: Strike | L2: Qty | M2: Amount | N2: Comission | O2: Total Profit | P2: Total loss | Q2: Total P&L | R2: Comment | S2: Profit % | T2: Profit probability (>70%) | U2: Max Win probab | V2: Max Loss | W2: Max Lose probab | X2: Return / Risk
A3: 45666 | B3: GOOGL | C3: 0.186 | D3: 0.32 | E3: 0.29 | F3: Y | G3: 0.1 | H3: Put | I3: Sell | J3: 45709 | K3: 180 | L3: 1 | M3: 311 | N3: 0.8 | O3: =M3-N3 -> 310.2 | Q3: =sum(O3:P3) -> 310.2 | R3: Put assigned | S3: =Q3/(K3*100*L3) -> 0.017233333 | T3: 0.81 | U3: 0.77 | V3: 17604 | W3: <1% | X3: 0.02
A4: 45666 | B4: AAPL | C4: 0.186 | D4: 0.246 | E4: 0.196 | F4: Y | G4: 0.05 | H4: Put | I4: Sell | J4: 45709 | K4: 220 | L4: 1 | M4: 249 | N4: 1.05 | O4: =M4-N4 -> 247.95 | Q4: =sum(O4:P4) -> 247.95 | R4: Expired OOM | S4: =Q4/(K4*100*L4) -> 0.011270455 | T4: 0.86 | U4: 0.82 | V4: 21647 | W4: <1% | X4: 0.01
A5: 45671 | B5: CROX | C5: 0.186 | D5: 0.55 | E5: 0.35 | F5: Y | G5: 0.1 | H5: Put | I5: Sell | J5: 45709 | K5: 95 | L5: 1 | M5: 331 | N5: 1.08 | O5: =M5-N5 -> 329.92 | Q5: =sum(O5:P5) -> 329.92 | R5: Expired OOM | S5: =Q5/(K5*100*L5) -> 0.034728421 | T5: 0.78 | U5: 0.72 | V5: 9146 | W5: <1% | X5: 0.03
A6: 45685 | B6: C | C6: 0.167 | D6: 0.216 | E6: 0.256 | F6: N | G6: 0.02 | H6: Put | I6: Sell | J6: 45709 | K6: 78 | L6: 1 | M6: 112 | N6: 1.05 | O6: =M6-N6 -> 110.95 | Q6: =sum(O6:P6) -> 110.95 | R6: Expired OOM | S6: =Q6/(K6*100*L6) -> 0.014224359 | T6: 0.74 | U6: 0.65 | V6: 7670 | W6: <1% | X6: 0.01
A7: 45694 | B7: NVDA | C7: 0.1549 | D7: 0.44 | E7: 0.67 | F7: N | G7: 0.02 | H7: Put | I7: Sell | J7: 45709 | K7: 121 | L7: 1 | M7: 196 | N7: 1.05 | O7: =M7-N7 -> 194.95 | Q7: =sum(O7:P7) -> 194.95 | R7: Expired OOM | S7: =Q7/(K7*100*L7) -> 0.01611157 | T7: 0.8 | U7: 0.74 | V7: 11891 | W7: <1% | X7: 0.02
A9: 45712 | B9: GOOGL | C9: 0.1749 | D9: 0.26 | E9: 0.36 | F9: N | G9: 0.03 | H9: Call | I9: Sell | J9: 45737 | K9: 190 | L9: 1 | M9: 177 | N9: 1.05 | O9: =M9-N9 -> 175.95 | Q9: =sum(O9:P9) -> 175.95 | R9: Expired OOM | S9: =Q9/(K9*100*L9) -> 0.0092605263 | T9: 0.8 | U9: 0.76
A10: 45712 | B10: AAPL | C10: 0.1749 | D10: 0.22 | E10: 0.3 | F10: N | G10: 0.03 | H10: Put | I10: Sell | J10: 45737 | K10: 237.5 | L10: 1 | M10: 218 | N10: 1.06 | O10: =M10-N10 -> 216.94 | Q10: =sum(O10:P10) -> 216.94 | R10: Put assigned | S10: =Q10/(K10*100*L10) -> 0.0091343158 | T10: 0.84 | U10: 0.8 | V10: 23466 | W10: <1% | X10: 0.01
A11: 45712 | B11: CROX | C11: 0.1749 | D11: 0.39 | E11: 0.77 | F11: N | G11: 0.15 | H11: Put | I11: Sell | J11: 45737 | K11: 100 | L11: 1 | M11: 214 | N11: 1.06 | O11: =M11-N11 -> 212.94 | Q11: =sum(O11:P11) -> 212.94 | R11: Expired OOM | S11: =Q11/(K11*100*L11) -> 0.021294 | T11: 0.78 | U11: 0.72 | V11: 9785 | W11: <1% | X11: 0.02
A12: 45712 | B12: CROX | C12: 0.1749 | D12: 0.39 | E12: 0.77 | F12: N | H12: Call | I12: Sell | J12: 45737 | K12: 115 | L12: 1 | M12: 121 | N12: 0.26 | O12: =M12-N12 -> 120.74 | Q12: =sum(O12:P12) -> 120.74 | R12: Expired OOM | S12: =Q12/(K12*100*L12) -> 0.01049913 | T12: 0.81 | U12: 0.78
A13: 45712 | B13: NVDA | C13: 0.1749 | D13: 0.64 | E13: 0.67 | F13: N | G13: 0.1 | H13: Put | I13: Sell | J13: 45737 | K13: 120 | L13: 1 | M13: 339 | N13: 0.81 | O13: =M13-N13 -> 338.19 | Q13: =sum(O13:P13) -> 338.19 | R13: Put assigned | S13: =Q13/(K13*100*L13) -> 0.0281825
A14: 45712 | B14: JD | C14: 0.1749 | D14: 0.4 | E14: 0.56 | F14: Y | G14: 0.03 | H14: Put | I14: Sell | J14: 45737 | K14: 36 | L14: 1 | M14: 112 | N14: 1.05 | O14: =M14-N14 -> 110.95 | Q14: =sum(O14:P14) -> 110.95 | R14: Expired OOM | S14: =Q14/(K14*100*L14) -> 0.030819444 | T14: 0.76 | U14: 0.7 | V14: 3477 | W14: <1% | X14: 0.03
A15: 45712 | B15: WING | C15: 0.1749 | D15: 0.38 | E15: 0.54 | F15: N | G15: 0.2 | H15: Put | I15: Sell | J15: 45737 | K15: 220 | L15: 1 | M15: 281 | N15: 0.02 | O15: =M15-N15 -> 280.98 | Q15: =sum(O15:P15) -> 280.98 | R15: Put assigned | S15: =Q15/(K15*100*L15) -> 0.012771818 | T15: 0.84 | U15: 0.81 | V15: 21664 | W15: <1% | X15: 0.01
A16: 45712 | B16: ASAN | C16: 0.1749 | D16: 1.04 | E16: 0.79 | F16: N | G16: 0.1 | H16: Put | I16: Sell | J16: 45737 | K16: 17.5 | L16: 4 | M16: 384 | N16: 1.36 | O16: =M16-N16 -> 382.64 | Q16: =sum(O16:P16) -> 382.64 | R16: Put assigned | S16: =Q16/(K16*100*L16) -> 0.054662857 | T16: 0.74 | U16: 0.66 | V16: 6541 | W16: <1% | X16: 0.06
A18: 45733 | B18: AAPL | C18: 0.2 | D18: 0.28 | E18: 0.295 | F18: N | G18: 0.05 | H18: Call | I18: Sell | J18: 45764 | K18: 225 | L18: 1 | M18: 306 | N18: 0.81 | O18: =M18-N18 -> 305.19 | Q18: =sum(O18:P18) -> 305.19 | R18: Expired OOM | S18: =Q18/(K18*100*L18) -> 0.013564 | T18: 0.75 | U18: 0.7 | W18: <1%
A19: 45743 | B19: WING | C19: 0.19 | D19: 0.43 | E19: 0.63 | F19: N | H19: Call | I19: Sell | J19: 45764 | K19: 240 | L19: 1 | M19: 576 | N19: 1.08 | O19: =M19-N19 -> 574.92 | Q19: =sum(O19:P19) -> 574.92 | R19: Expired OOM | S19: =Q19/(K19*100*L19) -> 0.023955 | T19: 0.73 | U19: 0.66 | W19: <1%
A20: 45743 | B20: GOOGL | C20: 0.19 | D20: 0.28 | E20: 0.3 | F20: N | H20: Call | I20: Sell | J20: 45764 | K20: 172.5 | L20: 1 | M20: 119 | N20: 1.05 | O20: =M20-N20 -> 117.95 | Q20: =sum(O20:P20) -> 117.95 | R20: Expired OOM | S20: =Q20/(K20*100*L20) -> 0.0068376812 | T20: 0.83 | U20: 0.8 | W20: <1%
A21: 45747 | B21: NEM | C21: 0.22 | D21: 0.33 | E21: 0.35 | F21: N | G21: 0.04 | H21: Put | I21: Sell | J21: 45764 | K21: 48 | L21: 1 | M21: 130 | N21: 1.05 | O21: =M21-N21 -> 128.95 | Q21: =sum(O21:P21) -> 128.95 | R21: Expired OOM | S21: =Q21/(K21*100*L21) -> 0.026864583 | T21: 0.68 | U21: 0.56 | W21: <1%
A22: 45747 | B22: NVDA | C22: 0.22 | D22: 0.49 | E22: 0.55 | F22: N | G22: 0.02 | H22: Call | I22: Sell | J22: 45764 | K22: 117 | L22: 1 | M22: 109 | N22: 1.05 | O22: =M22-N22 -> 107.95 | Q22: =sum(O22:P22) -> 107.95 | R22: Expired OOM | S22: =Q22/(K22*100*L22) -> 0.0092264957 | T22: 0.8 | U22: 0.76 | W22: <1%
